<?xml version="1.0"?>
<robot name="raskar">

  <material name="dark_yellow">
    <color rgba="0.8 0.8 0 1"/>
  </material>

  <material name="pale_grey">
    <color rgba="0.753 0.753 0.753 1"/>
  </material>

  <material name="shiny_black">
    <color rgba="0.251 0.251 0.251 1"/>
  </material>

  <!-- Gazebo initializer -->
  <gazebo>
    <static>false</static>
    
    <plugin name="gazebo_ros_control" filename="libgazebo_ros_control.so">
      <robotNamespace>/raskar</robotNamespace>
      <robotSimType>gazebo_ros_control/DefaultRobotHWSim</robotSimType>
      <legacyModeNS>true</legacyModeNS>
    </plugin>
  </gazebo>



  <!-- Used for fixing robot to Gazebo -->
  <!--link name="world"/>

  <joint name="fixed" type="fixed">
    <parent link="world"/>
    <child link="base_link"/>
  </joint-->

  <link name="base_link">
    <visual>
      <origin rpy="1.571 0 0" xyz="0 0 -0.075"/>
      <geometry>	
        <mesh filename="package://raskar_urdf/meshes/body_parts.stl" scale="0.001 0.001 0.001" />	
      </geometry>
      <material name="pale_grey"/>
    </visual>
    <collision>
      <origin rpy="0 0 0" xyz="0 0 0.15"/>
      <geometry>
        <!--box size="0.948 0.636 0.3"/-->
        <box size="0.998 0.678 0.35"/>
      </geometry>      
    </collision>
  </link>

  <joint name="base_link_to_wheel_left_back" type="continuous">
    <axis xyz="0 1 0"/>
    <parent link="base_link"/>
    <child link="wheel_left_back"/>
    <origin rpy="0 0 0" xyz="-0.260 0.2670 0.0635"/>
  </joint>

  <link name="wheel_left_back">
    <visual>
      <origin rpy="1.571 0 0" xyz="0 0 0"/>
      <geometry>	
        <mesh filename="package://raskar_urdf/meshes/5_in_mecanum.stl" scale="0.001 0.001 0.001" />	
      </geometry>
      <material name="dark_yellow"/>
    </visual>
  </link>

  <joint name="base_link_to_wheel_left_front" type="continuous">
    <axis xyz="0 1 0"/>
    <parent link="base_link"/>
    <child link="wheel_left_front"/>
    <origin rpy="0 0 0" xyz="0.260 0.2670 0.0635"/>
  </joint>

  <link name="wheel_left_front">
    <visual>
      <origin rpy="1.571 0 0" xyz="0 0 0"/>
      <geometry>	
        <mesh filename="package://raskar_urdf/meshes/5_in_mecanum.stl" scale="0.001 0.001 0.001" />	
      </geometry>
      <material name="dark_yellow"/>
    </visual>
  </link>


  <joint name="base_link_to_wheel_right_front" type="continuous">
    <axis xyz="0 1 0"/>
    <parent link="base_link"/>
    <child link="wheel_right_front"/>
    <origin rpy="0 0 0" xyz="0.260 -0.2670 0.0635"/>
  </joint>

  <link name="wheel_right_front">
    <visual>
      <origin rpy="1.571 0 0" xyz="0 0 0"/>
      <geometry>	
        <mesh filename="package://raskar_urdf/meshes/5_in_mecanum.stl" scale="0.001 0.001 0.001" />	
      </geometry>
      <material name="dark_yellow"/>
    </visual>
  </link>


  <joint name="base_link_to_wheel_right_back" type="continuous">
    <axis xyz="0 1 0"/>
    <parent link="base_link"/>
    <child link="wheel_right_back"/>
    <origin rpy="0 0 0" xyz="-0.260 -0.2670 0.0635"/>
  </joint>

  <link name="wheel_right_back">
    <visual>
      <origin rpy="1.571 0 0" xyz="0 0 0"/>
      <geometry>	
        <mesh filename="package://raskar_urdf/meshes/5_in_mecanum.stl" scale="0.001 0.001 0.001" />	
      </geometry>
      <material name="dark_yellow"/>
    </visual>
  </link>


  <!--link name="rplidar_a2_front">
    <visual>
      <origin rpy="1.571 0 3.1415" xyz="0 0 0"/>
      <geometry>	
        <mesh filename="package://raskar_urdf/meshes/rplidar_a2m4.stl" scale="0.000417 0.000417 0.000417" />	
      </geometry>
      <material name="shiny_black"/>
    </visual>
  </link>

  <joint name="base_link_to_rplidar_a2_front" type="fixed">
    <parent link="base_link"/>
    <child link="rplidar_a2_front"/>
    <origin rpy="0 0 -0.7853" xyz="0.415 -0.335 0.15"/>
  </joint-->






  <transmission name="tran1">
    <type>transmission_interface/SimpleTransmission</type>
    <joint name="base_link_to_wheel_left_back">
      <hardwareInterface>hardware_interface/EffortJointInterface</hardwareInterface>
    </joint>
    <actuator name="motor1">
      <hardwareInterface>hardware_interface/EffortJointInterface</hardwareInterface>
      <mechanicalReduction>1</mechanicalReduction>
    </actuator>
  </transmission>

  <transmission name="tran2">
    <type>transmission_interface/SimpleTransmission</type>
    <joint name="base_link_to_wheel_left_front">
      <hardwareInterface>hardware_interface/EffortJointInterface</hardwareInterface>
    </joint>
    <actuator name="motor2">
      <hardwareInterface>hardware_interface/EffortJointInterface</hardwareInterface>
      <mechanicalReduction>1</mechanicalReduction>
    </actuator>
  </transmission>

  <transmission name="tran3">
    <type>transmission_interface/SimpleTransmission</type>
    <joint name="base_link_to_wheel_right_front">
      <hardwareInterface>hardware_interface/EffortJointInterface</hardwareInterface>
    </joint>
    <actuator name="motor3">
      <hardwareInterface>hardware_interface/EffortJointInterface</hardwareInterface>
      <mechanicalReduction>1</mechanicalReduction>
    </actuator>
  </transmission>

  <transmission name="tran4">
    <type>transmission_interface/SimpleTransmission</type>
    <joint name="base_link_to_wheel_right_back">
      <hardwareInterface>hardware_interface/EffortJointInterface</hardwareInterface>
    </joint>
    <actuator name="motor4">
      <hardwareInterface>hardware_interface/EffortJointInterface</hardwareInterface>
      <mechanicalReduction>1</mechanicalReduction>
    </actuator>
  </transmission>



</robot>
