<sdf version='1.6'>
  <world name='default'>
    <light name='sun' type='directional'>
      <cast_shadows>1</cast_shadows>
      <pose frame=''>0 0 10 0 -0 0</pose>
      <diffuse>0.8 0.8 0.8 1</diffuse>
      <specular>0.1 0.1 0.1 1</specular>
      <attenuation>
        <range>1000</range>
        <constant>0.9</constant>
        <linear>0.01</linear>
        <quadratic>0.001</quadratic>
      </attenuation>
      <direction>-0.5 0.5 -1</direction>
    </light>
    <model name='ground_plane'>
      <static>1</static>
      <link name='link'>
        <collision name='collision'>
          <geometry>
            <plane>
              <normal>0 0 1</normal>
              <size>100 100</size>
            </plane>
          </geometry>
          <surface>
            <friction>
              <ode>
                <mu>100</mu>
                <mu2>50</mu2>
              </ode>
              <torsional>
                <ode/>
              </torsional>
            </friction>
            <contact>
              <ode/>
            </contact>
            <bounce/>
          </surface>
          <max_contacts>10</max_contacts>
        </collision>
        <visual name='visual'>
          <cast_shadows>0</cast_shadows>
          <geometry>
            <plane>
              <normal>0 0 1</normal>
              <size>100 100</size>
            </plane>
          </geometry>
          <material>
            <script>
              <uri>file://media/materials/scripts/gazebo.material</uri>
              <name>Gazebo/Grey</name>
            </script>
          </material>
        </visual>
        <self_collide>0</self_collide>
        <kinematic>0</kinematic>
        <gravity>1</gravity>
      </link>
    </model>
    <gravity>0 0 -9.8</gravity>
    <magnetic_field>6e-06 2.3e-05 -4.2e-05</magnetic_field>
    <atmosphere type='adiabatic'/>
    <physics name='default_physics' default='0' type='ode'>
      <max_step_size>0.001</max_step_size>
      <real_time_factor>1</real_time_factor>
      <real_time_update_rate>1000</real_time_update_rate>
    </physics>
    <scene>
      <ambient>0.4 0.4 0.4 1</ambient>
      <background>0.7 0.7 0.7 1</background>
      <shadows>1</shadows>
    </scene>
    <spherical_coordinates>
      <surface_model>EARTH_WGS84</surface_model>
      <latitude_deg>0</latitude_deg>
      <longitude_deg>0</longitude_deg>
      <elevation>0</elevation>
      <heading_deg>0</heading_deg>
    </spherical_coordinates>
    <model name='raskar_gazebo'>
      <link name='base_robot'>
        <pose frame=''>0 0 0 0 -0 0</pose>
        <inertial>
          <pose frame=''>0.021842 -0.017632 0.007895 0 -0 0</pose>
          <mass>1.9</mass>
          <inertia>
            <ixx>5.55647</ixx>
            <ixy>0.0131708</ixy>
            <ixz>-0.00589737</ixz>
            <iyy>7.34636</iyy>
            <iyz>0.00476053</iyz>
            <izz>2.7125</izz>
          </inertia>
        </inertial>
        <collision name='base_robot_collision'>
          <pose frame=''>0 0 0.25 0 -0 0</pose>
          <geometry>
            <box>
              <size>0.998 0.678 0.35</size>
            </box>
          </geometry>
          <max_contacts>10</max_contacts>
          <surface>
            <contact>
              <ode/>
            </contact>
            <bounce/>
            <friction>
              <torsional>
                <ode/>
              </torsional>
              <ode/>
            </friction>
          </surface>
        </collision>
        <visual name='base_robot_visual'>
          <pose frame=''>0 0 -0.075 1.571 -0 0</pose>
          <geometry>
            <mesh>
              <scale>1 1 1</scale>
              <uri>/home/frank/ws_raskar_urdf/src/raskar_urdf/meshes/body_parts.stl</uri>
            </mesh>
          </geometry>
        </visual>
        <visual name='base_robot_fixed_joint_lump__rplidar_a2_front_visual_1'>
          <pose frame=''>0.415 -0.335 0.15 1.571 0 2.3562</pose>
          <geometry>
            <mesh>
              <scale>1 1 1</scale>
              <uri>/home/frank/ws_raskar_urdf/src/raskar_urdf/meshes/rplidar_a2m4.stl</uri>
            </mesh>
          </geometry>
        </visual>
        <self_collide>0</self_collide>
        <kinematic>0</kinematic>
        <gravity>1</gravity>
      </link>
      <joint name='fixed' type='revolute'>
        <child>base_robot</child>
        <parent>world</parent>
        <axis>
          <limit>
            <lower>0</lower>
            <upper>0</upper>
          </limit>
          <dynamics>
            <damping>0</damping>
            <friction>0</friction>
            <spring_reference>0</spring_reference>
            <spring_stiffness>0</spring_stiffness>
          </dynamics>
          <use_parent_model_frame>1</use_parent_model_frame>
          <xyz>0 0 1</xyz>
        </axis>
      </joint>
      <link name='wheel_left_back'>
        <pose frame=''>-0.26 0.267 0.0635 0 -0 0</pose>
        <inertial>
          <pose frame=''>0 0 0 0 -0 0</pose>
          <mass>1.8</mass>
          <inertia>
            <ixx>0.0117145</ixx>
            <ixy>0</ixy>
            <ixz>0</ixz>
            <iyy>0.0117145</iyy>
            <iyz>0</iyz>
            <izz>0.00362903</izz>
          </inertia>
        </inertial>
        <visual name='wheel_left_back_visual'>
          <pose frame=''>0 0 0 1.571 -0 0</pose>
          <geometry>
            <mesh>
              <scale>1 1 1</scale>
              <uri>/home/frank/ws_raskar_urdf/src/raskar_urdf/meshes/5_in_mecanum.stl</uri>
            </mesh>
          </geometry>
          <material>
            <script>
              <name>Gazebo/dark_yellow</name>
              <uri>file://media/materials/scripts/gazebo.material</uri>
            </script>
          </material>
        </visual>
        <gravity>1</gravity>
        <velocity_decay/>
        <self_collide>0</self_collide>
        <kinematic>0</kinematic>
      </link>
      <joint name='base_robot_to_wheel_left_back' type='revolute'>
        <child>wheel_left_back</child>
        <parent>base_robot</parent>
        <axis>
          <xyz>0 1 0</xyz>
          <limit>
            <lower>-1e+16</lower>
            <upper>1e+16</upper>
          </limit>
          <dynamics>
            <damping>0.7</damping>
            <friction>0</friction>
            <spring_reference>0</spring_reference>
            <spring_stiffness>0</spring_stiffness>
          </dynamics>
          <use_parent_model_frame>1</use_parent_model_frame>
        </axis>
      </joint>
      <link name='wheel_left_front'>
        <pose frame=''>0.26 0.267 0.0635 0 -0 0</pose>
        <inertial>
          <pose frame=''>0 0 0 0 -0 0</pose>
          <mass>1.8</mass>
          <inertia>
            <ixx>0.0117145</ixx>
            <ixy>0</ixy>
            <ixz>0</ixz>
            <iyy>0.0117145</iyy>
            <iyz>0</iyz>
            <izz>0.00362903</izz>
          </inertia>
        </inertial>
        <visual name='wheel_left_front_visual'>
          <pose frame=''>0 0 0 1.571 -0 0</pose>
          <geometry>
            <mesh>
              <scale>1 1 1</scale>
              <uri>/home/frank/ws_raskar_urdf/src/raskar_urdf/meshes/5_in_mecanum.stl</uri>
            </mesh>
          </geometry>
          <material>
            <script>
              <name>Gazebo/dark_yellow</name>
              <uri>file://media/materials/scripts/gazebo.material</uri>
            </script>
          </material>
        </visual>
        <gravity>1</gravity>
        <velocity_decay/>
        <self_collide>0</self_collide>
        <kinematic>0</kinematic>
      </link>
      <joint name='base_robot_to_wheel_left_front' type='revolute'>
        <child>wheel_left_front</child>
        <parent>base_robot</parent>
        <axis>
          <xyz>0 1 0</xyz>
          <limit>
            <lower>-1e+16</lower>
            <upper>1e+16</upper>
          </limit>
          <dynamics>
            <damping>0.7</damping>
            <friction>0</friction>
            <spring_reference>0</spring_reference>
            <spring_stiffness>0</spring_stiffness>
          </dynamics>
          <use_parent_model_frame>1</use_parent_model_frame>
        </axis>
      </joint>
      <link name='wheel_right_back'>
        <pose frame=''>-0.26 -0.267 0.0635 0 -0 0</pose>
        <inertial>
          <pose frame=''>0 0 0 0 -0 0</pose>
          <mass>1.8</mass>
          <inertia>
            <ixx>0.0117145</ixx>
            <ixy>0</ixy>
            <ixz>0</ixz>
            <iyy>0.0117145</iyy>
            <iyz>0</iyz>
            <izz>0.00362903</izz>
          </inertia>
        </inertial>
        <visual name='wheel_right_back_visual'>
          <pose frame=''>0 0 0 1.571 -0 0</pose>
          <geometry>
            <mesh>
              <scale>1 1 1</scale>
              <uri>/home/frank/ws_raskar_urdf/src/raskar_urdf/meshes/5_in_mecanum.stl</uri>
            </mesh>
          </geometry>
          <material>
            <script>
              <name>Gazebo/dark_yellow</name>
              <uri>file://media/materials/scripts/gazebo.material</uri>
            </script>
          </material>
        </visual>
        <gravity>1</gravity>
        <velocity_decay/>
        <self_collide>0</self_collide>
        <kinematic>0</kinematic>
      </link>
      <joint name='base_robot_to_wheel_right_back' type='revolute'>
        <child>wheel_right_back</child>
        <parent>base_robot</parent>
        <axis>
          <xyz>0 1 0</xyz>
          <limit>
            <lower>-1e+16</lower>
            <upper>1e+16</upper>
          </limit>
          <dynamics>
            <damping>0.7</damping>
            <friction>0</friction>
            <spring_reference>0</spring_reference>
            <spring_stiffness>0</spring_stiffness>
          </dynamics>
          <use_parent_model_frame>1</use_parent_model_frame>
        </axis>
      </joint>
      <link name='wheel_right_front'>
        <pose frame=''>0.26 -0.267 0.0635 0 -0 0</pose>
        <inertial>
          <pose frame=''>0 0 0 0 -0 0</pose>
          <mass>1.8</mass>
          <inertia>
            <ixx>0.0117145</ixx>
            <ixy>0</ixy>
            <ixz>0</ixz>
            <iyy>0.0117145</iyy>
            <iyz>0</iyz>
            <izz>0.00362903</izz>
          </inertia>
        </inertial>
        <visual name='wheel_right_front_visual'>
          <pose frame=''>0 0 0 1.571 -0 0</pose>
          <geometry>
            <mesh>
              <scale>1 1 1</scale>
              <uri>/home/frank/ws_raskar_urdf/src/raskar_urdf/meshes/5_in_mecanum.stl</uri>
            </mesh>
          </geometry>
          <material>
            <script>
              <name>Gazebo/dark_yellow</name>
              <uri>file://media/materials/scripts/gazebo.material</uri>
            </script>
          </material>
        </visual>
        <gravity>1</gravity>
        <velocity_decay/>
        <self_collide>0</self_collide>
        <kinematic>0</kinematic>
      </link>
      <joint name='base_robot_to_wheel_right_front' type='revolute'>
        <child>wheel_right_front</child>
        <parent>base_robot</parent>
        <axis>
          <xyz>0 1 0</xyz>
          <limit>
            <lower>-1e+16</lower>
            <upper>1e+16</upper>
          </limit>
          <dynamics>
            <damping>0.7</damping>
            <friction>0</friction>
            <spring_reference>0</spring_reference>
            <spring_stiffness>0</spring_stiffness>
          </dynamics>
          <use_parent_model_frame>1</use_parent_model_frame>
        </axis>
      </joint>
      <static>0</static>
      <plugin name='gazebo_ros_control' filename='libgazebo_ros_control.so'>
        <robotNamespace>/raskar</robotNamespace>
        <robotSimType>gazebo_ros_control/DefaultRobotHWSim</robotSimType>
        <legacyModeNS>true</legacyModeNS>
      </plugin>
      <pose frame=''>0 0 0 0 -0 0</pose>
    </model>
    <state world_name='default'>
      <sim_time>80 93000000</sim_time>
      <real_time>80 766191593</real_time>
      <wall_time>1576829234 324971313</wall_time>
      <iterations>80093</iterations>
      <model name='ground_plane'>
        <pose frame=''>0 0 0 0 -0 0</pose>
        <scale>1 1 1</scale>
        <link name='link'>
          <pose frame=''>0 0 0 0 -0 0</pose>
          <velocity>0 0 0 0 -0 0</velocity>
          <acceleration>0 0 0 0 -0 0</acceleration>
          <wrench>0 0 0 0 -0 0</wrench>
        </link>
      </model>
      <model name='raskar_gazebo'>
        <pose frame=''>0 0 0 0 -0 0</pose>
        <scale>1 1 1</scale>
        <link name='base_robot'>
          <pose frame=''>0 0 0 0 -0 0</pose>
          <velocity>0 0 0 0 -0 0</velocity>
          <acceleration>0 0 0 0 -0 0</acceleration>
          <wrench>0 0 0 0 -0 0</wrench>
        </link>
        <link name='wheel_left_back'>
          <pose frame=''>-0.26 0.267 0.0635 0 -0 0</pose>
          <velocity>0 0 0 0 -0 0</velocity>
          <acceleration>0 0 0 0 -0 0</acceleration>
          <wrench>0 0 0 0 -0 0</wrench>
        </link>
        <link name='wheel_left_front'>
          <pose frame=''>0.26 0.267 0.0635 0 -0 0</pose>
          <velocity>0 0 0 0 -0 0</velocity>
          <acceleration>0 0 0 0 -0 0</acceleration>
          <wrench>0 0 0 0 -0 0</wrench>
        </link>
        <link name='wheel_right_back'>
          <pose frame=''>-0.26 -0.267 0.0635 0 -0 0</pose>
          <velocity>0 0 0 0 -0 0</velocity>
          <acceleration>0 0 0 0 -0 0</acceleration>
          <wrench>0 0 0 0 -0 0</wrench>
        </link>
        <link name='wheel_right_front'>
          <pose frame=''>0.26 -0.267 0.0635 0 -0 0</pose>
          <velocity>0 0 0 0 -0 0</velocity>
          <acceleration>0 0 0 0 -0 0</acceleration>
          <wrench>0 0 0 0 -0 0</wrench>
        </link>
      </model>
      <light name='sun'>
        <pose frame=''>0 0 10 0 -0 0</pose>
      </light>
    </state>
    <gui fullscreen='0'>
      <camera name='user_camera'>
        <pose frame=''>-2.15795 -0.405152 0.480136 0 0.247643 0.168194</pose>
        <view_controller>orbit</view_controller>
        <projection_type>perspective</projection_type>
      </camera>
    </gui>
  </world>
</sdf>
