<sdf version='1.6'>
  <world name='default'>
    <light name='sun' type='directional'>
      <cast_shadows>1</cast_shadows>
      <pose frame=''>0 0 10 0 -0 0</pose>
      <diffuse>0.8 0.8 0.8 1</diffuse>
      <specular>0.2 0.2 0.2 1</specular>
      <attenuation>
        <range>1000</range>
        <constant>0.9</constant>
        <linear>0.01</linear>
        <quadratic>0.001</quadratic>
      </attenuation>
      <direction>-0.5 0.1 -0.9</direction>
    </light>
    <model name='ground_plane'>
      <static>1</static>
      <link name='link'>
        <collision name='collision'>
          <geometry>
            <plane>
              <normal>0 0 1</normal>
              <size>100 100</size>
            </plane>
          </geometry>
          <surface>
            <contact>
              <collide_bitmask>65535</collide_bitmask>
              <ode/>
            </contact>
            <friction>
              <ode>
                <mu>100</mu>
                <mu2>50</mu2>
              </ode>
              <torsional>
                <ode/>
              </torsional>
            </friction>
            <bounce/>
          </surface>
          <max_contacts>10</max_contacts>
        </collision>
        <visual name='visual'>
          <cast_shadows>0</cast_shadows>
          <geometry>
            <plane>
              <normal>0 0 1</normal>
              <size>100 100</size>
            </plane>
          </geometry>
          <material>
            <script>
              <uri>file://media/materials/scripts/gazebo.material</uri>
              <name>Gazebo/Grey</name>
            </script>
          </material>
        </visual>
        <self_collide>0</self_collide>
        <enable_wind>0</enable_wind>
        <kinematic>0</kinematic>
      </link>
    </model>
    <gravity>0 0 -9.8</gravity>
    <magnetic_field>6e-06 2.3e-05 -4.2e-05</magnetic_field>
    <atmosphere type='adiabatic'/>
    <physics name='default_physics' default='0' type='ode'>
      <max_step_size>0.001</max_step_size>
      <real_time_factor>1</real_time_factor>
      <real_time_update_rate>1000</real_time_update_rate>
    </physics>
    <scene>
      <ambient>0.4 0.4 0.4 1</ambient>
      <background>0.7 0.7 0.7 1</background>
      <shadows>1</shadows>
    </scene>
    <audio>
      <device>default</device>
    </audio>
    <wind/>
    <spherical_coordinates>
      <surface_model>EARTH_WGS84</surface_model>
      <latitude_deg>0</latitude_deg>
      <longitude_deg>0</longitude_deg>
      <elevation>0</elevation>
      <heading_deg>0</heading_deg>
    </spherical_coordinates>
    <model name='raskar_gazebo'>
      <link name='base_footprint'>
        <pose frame=''>0 0 0 0 -0 0</pose>
        <inertial>
          <pose frame=''>0.001867 -0 0.140153 0 -0 0</pose>
          <mass>68.71</mass>
          <inertia>
            <ixx>5.58141</ixx>
            <ixy>-6.47728e-21</ixy>
            <ixz>0.00600321</ixz>
            <iyy>7.45983</iyy>
            <iyz>2.94002e-21</iyz>
            <izz>2.83403</izz>
          </inertia>
        </inertial>
        <collision name='base_footprint_fixed_joint_lump__base_link_collision'>
          <pose frame=''>0 0 0.141 0 -0 0</pose>
          <geometry>
            <box>
              <size>0.998 0.678 0.3</size>
            </box>
          </geometry>
          <max_contacts>10</max_contacts>
          <surface>
            <contact>
              <ode/>
            </contact>
            <bounce/>
            <friction>
              <torsional>
                <ode/>
              </torsional>
              <ode/>
            </friction>
          </surface>
        </collision>
        <collision name='base_footprint_fixed_joint_lump__bk_corner_left_ultrasound_collision_1'>
          <pose frame=''>-0.41038 0.25038 0.019 0 -0 2.35619</pose>
          <geometry>
            <mesh>
              <scale>0.001 0.001 0.001</scale>
              <uri>/home/frank/Documents/ws_raskar/ws_raskar/src/raskar_urdf/meshes/ultrasound_hc_sr04.stl</uri>
            </mesh>
          </geometry>
          <surface>
            <contact>
              <ode/>
            </contact>
            <friction>
              <ode/>
              <torsional>
                <ode/>
              </torsional>
            </friction>
            <bounce/>
          </surface>
          <max_contacts>10</max_contacts>
        </collision>
        <collision name='base_footprint_fixed_joint_lump__bk_corner_right_ultrasound_collision_2'>
          <pose frame=''>-0.41038 -0.25038 0.019 0 -0 -2.35619</pose>
          <geometry>
            <mesh>
              <scale>0.001 0.001 0.001</scale>
              <uri>/home/frank/Documents/ws_raskar/ws_raskar/src/raskar_urdf/meshes/ultrasound_hc_sr04.stl</uri>
            </mesh>
          </geometry>
          <surface>
            <contact>
              <ode/>
            </contact>
            <friction>
              <ode/>
              <torsional>
                <ode/>
              </torsional>
            </friction>
            <bounce/>
          </surface>
          <max_contacts>10</max_contacts>
        </collision>
        <collision name='base_footprint_fixed_joint_lump__fr_center_imu_collision_3'>
          <pose frame=''>0.4 0 0.2585 0 -0 0</pose>
          <geometry>
            <mesh>
              <scale>0.1 0.1 0.1</scale>
              <uri>/home/frank/Documents/ws_raskar/ws_raskar/src/imu_bosch/ciss_ros_wrapper/src/ciss_imu/meshes/ciss_bosch.stl</uri>
            </mesh>
          </geometry>
          <surface>
            <contact>
              <ode/>
            </contact>
            <friction>
              <ode/>
              <torsional>
                <ode/>
              </torsional>
            </friction>
            <bounce/>
          </surface>
          <max_contacts>10</max_contacts>
        </collision>
        <collision name='base_footprint_fixed_joint_lump__fr_corner_left_ultrasound_collision_4'>
          <pose frame=''>0.41038 0.25038 0.019 0 -0 0.785398</pose>
          <geometry>
            <mesh>
              <scale>0.001 0.001 0.001</scale>
              <uri>/home/frank/Documents/ws_raskar/ws_raskar/src/raskar_urdf/meshes/ultrasound_hc_sr04.stl</uri>
            </mesh>
          </geometry>
          <surface>
            <contact>
              <ode/>
            </contact>
            <friction>
              <ode/>
              <torsional>
                <ode/>
              </torsional>
            </friction>
            <bounce/>
          </surface>
          <max_contacts>10</max_contacts>
        </collision>
        <collision name='base_footprint_fixed_joint_lump__fr_corner_right_ultrasound_collision_5'>
          <pose frame=''>0.41038 -0.25038 0.019 0 0 -0.785398</pose>
          <geometry>
            <mesh>
              <scale>0.001 0.001 0.001</scale>
              <uri>/home/frank/Documents/ws_raskar/ws_raskar/src/raskar_urdf/meshes/ultrasound_hc_sr04.stl</uri>
            </mesh>
          </geometry>
          <surface>
            <contact>
              <ode/>
            </contact>
            <friction>
              <ode/>
              <torsional>
                <ode/>
              </torsional>
            </friction>
            <bounce/>
          </surface>
          <max_contacts>10</max_contacts>
        </collision>
        <collision name='base_footprint_fixed_joint_lump__fr_nocorner_center_lidar_collision_6'>
          <pose frame=''>0.33 0 0.279 0 -0 0</pose>
          <geometry>
            <cylinder>
              <length>0.041</length>
              <radius>0.038</radius>
            </cylinder>
          </geometry>
          <surface>
            <contact>
              <ode/>
            </contact>
            <friction>
              <ode/>
              <torsional>
                <ode/>
              </torsional>
            </friction>
            <bounce/>
          </surface>
          <max_contacts>10</max_contacts>
        </collision>
        <collision name='base_footprint_fixed_joint_lump__fr_nocorner_left_ultrasound_collision_7'>
          <pose frame=''>0.45639 0.1 0.019 0 -0 0</pose>
          <geometry>
            <mesh>
              <scale>0.001 0.001 0.001</scale>
              <uri>/home/frank/Documents/ws_raskar/ws_raskar/src/raskar_urdf/meshes/ultrasound_hc_sr04.stl</uri>
            </mesh>
          </geometry>
          <surface>
            <contact>
              <ode/>
            </contact>
            <friction>
              <ode/>
              <torsional>
                <ode/>
              </torsional>
            </friction>
            <bounce/>
          </surface>
          <max_contacts>10</max_contacts>
        </collision>
        <collision name='base_footprint_fixed_joint_lump__fr_nocorner_right_ultrasound_collision_8'>
          <pose frame=''>0.45639 -0.1 0.019 0 -0 0</pose>
          <geometry>
            <mesh>
              <scale>0.001 0.001 0.001</scale>
              <uri>/home/frank/Documents/ws_raskar/ws_raskar/src/raskar_urdf/meshes/ultrasound_hc_sr04.stl</uri>
            </mesh>
          </geometry>
          <surface>
            <contact>
              <ode/>
            </contact>
            <friction>
              <ode/>
              <torsional>
                <ode/>
              </torsional>
            </friction>
            <bounce/>
          </surface>
          <max_contacts>10</max_contacts>
        </collision>
        <visual name='base_footprint_visual'>
          <pose frame=''>0 0 0 0 -0 0</pose>
          <geometry>
            <box>
              <size>0.001 0.001 0.001</size>
            </box>
          </geometry>
          <material>
            <script>
              <uri>__default__</uri>
              <name>__default__</name>
            </script>
          </material>
        </visual>
        <visual name='base_footprint_fixed_joint_lump__base_link_visual_1'>
          <pose frame=''>0 0 -0.0477 1.571 -0 0</pose>
          <geometry>
            <mesh>
              <scale>0.001 0.001 0.001</scale>
              <uri>/home/frank/Documents/ws_raskar/ws_raskar/src/raskar_urdf/meshes/body_parts.stl</uri>
            </mesh>
          </geometry>
        </visual>
        <visual name='base_footprint_fixed_joint_lump__bk_corner_left_ultrasound_visual_2'>
          <pose frame=''>-0.41038 0.25038 0.019 1.5708 -0 -2.35619</pose>
          <geometry>
            <mesh>
              <scale>0.001 0.001 0.001</scale>
              <uri>/home/frank/Documents/ws_raskar/ws_raskar/src/raskar_urdf/meshes/ultrasound_hc_sr04.stl</uri>
            </mesh>
          </geometry>
          <material>
            <script>
              <name>Gazebo/Blue</name>
              <uri>file://media/materials/scripts/gazebo.material</uri>
            </script>
          </material>
        </visual>
        <visual name='base_footprint_fixed_joint_lump__bk_corner_right_ultrasound_visual_3'>
          <pose frame=''>-0.41038 -0.25038 0.019 1.5708 -0 -0.785398</pose>
          <geometry>
            <mesh>
              <scale>0.001 0.001 0.001</scale>
              <uri>/home/frank/Documents/ws_raskar/ws_raskar/src/raskar_urdf/meshes/ultrasound_hc_sr04.stl</uri>
            </mesh>
          </geometry>
          <material>
            <script>
              <name>Gazebo/Blue</name>
              <uri>file://media/materials/scripts/gazebo.material</uri>
            </script>
          </material>
        </visual>
        <visual name='base_footprint_fixed_joint_lump__fr_center_imu_visual_4'>
          <pose frame=''>0.4 0 0.2585 0 -0 0</pose>
          <geometry>
            <mesh>
              <scale>0.1 0.1 0.1</scale>
              <uri>/home/frank/Documents/ws_raskar/ws_raskar/src/imu_bosch/ciss_ros_wrapper/src/ciss_imu/meshes/ciss_bosch.stl</uri>
            </mesh>
          </geometry>
          <material>
            <script>
              <name>Gazebo/White</name>
              <uri>file://media/materials/scripts/gazebo.material</uri>
            </script>
          </material>
        </visual>
        <visual name='base_footprint_fixed_joint_lump__fr_corner_left_ultrasound_visual_5'>
          <pose frame=''>0.41038 0.25038 0.019 1.5708 -0 2.35619</pose>
          <geometry>
            <mesh>
              <scale>0.001 0.001 0.001</scale>
              <uri>/home/frank/Documents/ws_raskar/ws_raskar/src/raskar_urdf/meshes/ultrasound_hc_sr04.stl</uri>
            </mesh>
          </geometry>
          <material>
            <script>
              <name>Gazebo/Blue</name>
              <uri>file://media/materials/scripts/gazebo.material</uri>
            </script>
          </material>
        </visual>
        <visual name='base_footprint_fixed_joint_lump__fr_corner_right_ultrasound_visual_6'>
          <pose frame=''>0.41038 -0.25038 0.019 1.5708 0 0.785398</pose>
          <geometry>
            <mesh>
              <scale>0.001 0.001 0.001</scale>
              <uri>/home/frank/Documents/ws_raskar/ws_raskar/src/raskar_urdf/meshes/ultrasound_hc_sr04.stl</uri>
            </mesh>
          </geometry>
          <material>
            <script>
              <name>Gazebo/Blue</name>
              <uri>file://media/materials/scripts/gazebo.material</uri>
            </script>
          </material>
        </visual>
        <visual name='base_footprint_fixed_joint_lump__fr_nocorner_center_lidar_visual_7'>
          <pose frame=''>0.33 0 0.279 0 -0 0</pose>
          <geometry>
            <cylinder>
              <length>0.041</length>
              <radius>0.038</radius>
            </cylinder>
          </geometry>
          <material>
            <script>
              <name>Gazebo/Black</name>
              <uri>file://media/materials/scripts/gazebo.material</uri>
            </script>
          </material>
        </visual>
        <visual name='base_footprint_fixed_joint_lump__fr_nocorner_left_ultrasound_visual_8'>
          <pose frame=''>0.45639 0.1 0.019 1.5708 -0 1.5708</pose>
          <geometry>
            <mesh>
              <scale>0.001 0.001 0.001</scale>
              <uri>/home/frank/Documents/ws_raskar/ws_raskar/src/raskar_urdf/meshes/ultrasound_hc_sr04.stl</uri>
            </mesh>
          </geometry>
          <material>
            <script>
              <name>Gazebo/Blue</name>
              <uri>file://media/materials/scripts/gazebo.material</uri>
            </script>
          </material>
        </visual>
        <visual name='base_footprint_fixed_joint_lump__fr_nocorner_right_ultrasound_visual_9'>
          <pose frame=''>0.45639 -0.1 0.019 1.5708 -0 1.5708</pose>
          <geometry>
            <mesh>
              <scale>0.001 0.001 0.001</scale>
              <uri>/home/frank/Documents/ws_raskar/ws_raskar/src/raskar_urdf/meshes/ultrasound_hc_sr04.stl</uri>
            </mesh>
          </geometry>
          <material>
            <script>
              <name>Gazebo/Blue</name>
              <uri>file://media/materials/scripts/gazebo.material</uri>
            </script>
          </material>
        </visual>
        <velocity_decay/>
        <velocity_decay/>
        <velocity_decay/>
        <velocity_decay/>
        <velocity_decay/>
        <velocity_decay/>
        <velocity_decay/>
        <velocity_decay/>
        <gravity>0</gravity>
        <velocity_decay/>
        <self_collide>0</self_collide>
        <enable_wind>0</enable_wind>
        <kinematic>0</kinematic>
      </link>
      <link name='bk_left_wheel'>
        <pose frame=''>-0.26 0.267 0.0285 0 -0 0</pose>
        <inertial>
          <pose frame=''>0 0 0 0 -0 0</pose>
          <mass>1.8</mass>
          <inertia>
            <ixx>0.00246791</ixx>
            <ixy>0</ixy>
            <ixz>0</ixz>
            <iyy>0.00246791</iyy>
            <iyz>0</iyz>
            <izz>0.00362903</izz>
          </inertia>
        </inertial>
        <collision name='bk_left_wheel_collision'>
          <pose frame=''>0 0 0 1.5708 -0 0</pose>
          <geometry>
            <mesh>
              <scale>0.001 0.001 0.001</scale>
              <uri>/home/frank/Documents/ws_raskar/ws_raskar/src/raskar_urdf/meshes/5_in_mecanum.stl</uri>
            </mesh>
          </geometry>
          <surface>
            <contact>
              <ode>
                <kp>1e+07</kp>
                <kd>1</kd>
              </ode>
            </contact>
            <friction>
              <ode>
                <mu>1</mu>
                <mu2>1</mu2>
                <fdir1>1 0 0</fdir1>
              </ode>
              <torsional>
                <ode/>
              </torsional>
            </friction>
            <bounce/>
          </surface>
          <max_contacts>10</max_contacts>
        </collision>
        <visual name='bk_left_wheel_visual'>
          <pose frame=''>0 0 0 1.5708 -0 0</pose>
          <geometry>
            <mesh>
              <scale>0.001 0.001 0.001</scale>
              <uri>/home/frank/Documents/ws_raskar/ws_raskar/src/raskar_urdf/meshes/5_in_mecanum.stl</uri>
            </mesh>
          </geometry>
          <material>
            <script>
              <name>Gazebo/Grey</name>
              <uri>file://media/materials/scripts/gazebo.material</uri>
            </script>
          </material>
        </visual>
        <gravity>1</gravity>
        <velocity_decay/>
        <self_collide>0</self_collide>
        <enable_wind>0</enable_wind>
        <kinematic>0</kinematic>
      </link>
      <joint name='bk_left_wheel_joint' type='revolute'>
        <child>bk_left_wheel</child>
        <parent>base_footprint</parent>
        <axis>
          <xyz>0 1 0</xyz>
          <limit>
            <lower>-1e+16</lower>
            <upper>1e+16</upper>
          </limit>
          <dynamics>
            <spring_reference>0</spring_reference>
            <spring_stiffness>0</spring_stiffness>
          </dynamics>
          <use_parent_model_frame>1</use_parent_model_frame>
        </axis>
      </joint>
      <link name='bk_right_wheel'>
        <pose frame=''>-0.26 -0.267 0.0285 0 -0 0</pose>
        <inertial>
          <pose frame=''>0 0 0 0 -0 0</pose>
          <mass>1.8</mass>
          <inertia>
            <ixx>0.00246791</ixx>
            <ixy>0</ixy>
            <ixz>0</ixz>
            <iyy>0.00246791</iyy>
            <iyz>0</iyz>
            <izz>0.00362903</izz>
          </inertia>
        </inertial>
        <collision name='bk_right_wheel_collision'>
          <pose frame=''>0 0 0 1.5708 -0 0</pose>
          <geometry>
            <mesh>
              <scale>0.001 0.001 0.001</scale>
              <uri>/home/frank/Documents/ws_raskar/ws_raskar/src/raskar_urdf/meshes/5_in_mecanum.stl</uri>
            </mesh>
          </geometry>
          <surface>
            <contact>
              <ode>
                <kp>1e+07</kp>
                <kd>1</kd>
              </ode>
            </contact>
            <friction>
              <ode>
                <mu>1</mu>
                <mu2>1</mu2>
                <fdir1>1 0 0</fdir1>
              </ode>
              <torsional>
                <ode/>
              </torsional>
            </friction>
            <bounce/>
          </surface>
          <max_contacts>10</max_contacts>
        </collision>
        <visual name='bk_right_wheel_visual'>
          <pose frame=''>0 0 0 1.5708 -0 0</pose>
          <geometry>
            <mesh>
              <scale>0.001 0.001 0.001</scale>
              <uri>/home/frank/Documents/ws_raskar/ws_raskar/src/raskar_urdf/meshes/5_in_mecanum.stl</uri>
            </mesh>
          </geometry>
          <material>
            <script>
              <name>Gazebo/Grey</name>
              <uri>file://media/materials/scripts/gazebo.material</uri>
            </script>
          </material>
        </visual>
        <gravity>1</gravity>
        <velocity_decay/>
        <self_collide>0</self_collide>
        <enable_wind>0</enable_wind>
        <kinematic>0</kinematic>
      </link>
      <joint name='bk_right_wheel_joint' type='revolute'>
        <child>bk_right_wheel</child>
        <parent>base_footprint</parent>
        <axis>
          <xyz>0 1 0</xyz>
          <limit>
            <lower>-1e+16</lower>
            <upper>1e+16</upper>
          </limit>
          <dynamics>
            <spring_reference>0</spring_reference>
            <spring_stiffness>0</spring_stiffness>
          </dynamics>
          <use_parent_model_frame>1</use_parent_model_frame>
        </axis>
      </joint>
      <link name='fr_left_wheel'>
        <pose frame=''>0.26 0.267 0.0285 0 -0 0</pose>
        <inertial>
          <pose frame=''>0 0 0 0 -0 0</pose>
          <mass>1.8</mass>
          <inertia>
            <ixx>0.00246791</ixx>
            <ixy>0</ixy>
            <ixz>0</ixz>
            <iyy>0.00246791</iyy>
            <iyz>0</iyz>
            <izz>0.00362903</izz>
          </inertia>
        </inertial>
        <collision name='fr_left_wheel_collision'>
          <pose frame=''>0 0 0 1.5708 -0 0</pose>
          <geometry>
            <mesh>
              <scale>0.001 0.001 0.001</scale>
              <uri>/home/frank/Documents/ws_raskar/ws_raskar/src/raskar_urdf/meshes/5_in_mecanum.stl</uri>
            </mesh>
          </geometry>
          <surface>
            <contact>
              <ode>
                <kp>1e+07</kp>
                <kd>1</kd>
              </ode>
            </contact>
            <friction>
              <ode>
                <mu>1</mu>
                <mu2>1</mu2>
                <fdir1>1 0 0</fdir1>
              </ode>
              <torsional>
                <ode/>
              </torsional>
            </friction>
            <bounce/>
          </surface>
          <max_contacts>10</max_contacts>
        </collision>
        <visual name='fr_left_wheel_visual'>
          <pose frame=''>0 0 0 1.5708 -0 0</pose>
          <geometry>
            <mesh>
              <scale>0.001 0.001 0.001</scale>
              <uri>/home/frank/Documents/ws_raskar/ws_raskar/src/raskar_urdf/meshes/5_in_mecanum.stl</uri>
            </mesh>
          </geometry>
          <material>
            <script>
              <name>Gazebo/Grey</name>
              <uri>file://media/materials/scripts/gazebo.material</uri>
            </script>
          </material>
        </visual>
        <gravity>1</gravity>
        <velocity_decay/>
        <self_collide>0</self_collide>
        <enable_wind>0</enable_wind>
        <kinematic>0</kinematic>
      </link>
      <joint name='fr_left_wheel_joint' type='revolute'>
        <child>fr_left_wheel</child>
        <parent>base_footprint</parent>
        <axis>
          <xyz>0 1 0</xyz>
          <limit>
            <lower>-1e+16</lower>
            <upper>1e+16</upper>
          </limit>
          <dynamics>
            <spring_reference>0</spring_reference>
            <spring_stiffness>0</spring_stiffness>
          </dynamics>
          <use_parent_model_frame>1</use_parent_model_frame>
        </axis>
      </joint>
      <link name='fr_right_wheel'>
        <pose frame=''>0.26 -0.267 0.0285 0 -0 0</pose>
        <inertial>
          <pose frame=''>0 0 0 0 -0 0</pose>
          <mass>1.8</mass>
          <inertia>
            <ixx>0.00246791</ixx>
            <ixy>0</ixy>
            <ixz>0</ixz>
            <iyy>0.00246791</iyy>
            <iyz>0</iyz>
            <izz>0.00362903</izz>
          </inertia>
        </inertial>
        <collision name='fr_right_wheel_collision'>
          <pose frame=''>0 0 0 1.5708 -0 0</pose>
          <geometry>
            <mesh>
              <scale>0.001 0.001 0.001</scale>
              <uri>/home/frank/Documents/ws_raskar/ws_raskar/src/raskar_urdf/meshes/5_in_mecanum.stl</uri>
            </mesh>
          </geometry>
          <surface>
            <contact>
              <ode>
                <kp>1e+07</kp>
                <kd>1</kd>
              </ode>
            </contact>
            <friction>
              <ode>
                <mu>1</mu>
                <mu2>1</mu2>
                <fdir1>1 0 0</fdir1>
              </ode>
              <torsional>
                <ode/>
              </torsional>
            </friction>
            <bounce/>
          </surface>
          <max_contacts>10</max_contacts>
        </collision>
        <visual name='fr_right_wheel_visual'>
          <pose frame=''>0 0 0 1.5708 -0 0</pose>
          <geometry>
            <mesh>
              <scale>0.001 0.001 0.001</scale>
              <uri>/home/frank/Documents/ws_raskar/ws_raskar/src/raskar_urdf/meshes/5_in_mecanum.stl</uri>
            </mesh>
          </geometry>
          <material>
            <script>
              <name>Gazebo/Grey</name>
              <uri>file://media/materials/scripts/gazebo.material</uri>
            </script>
          </material>
        </visual>
        <gravity>1</gravity>
        <velocity_decay/>
        <self_collide>0</self_collide>
        <enable_wind>0</enable_wind>
        <kinematic>0</kinematic>
      </link>
      <joint name='fr_right_wheel_joint' type='revolute'>
        <child>fr_right_wheel</child>
        <parent>base_footprint</parent>
        <axis>
          <xyz>0 1 0</xyz>
          <limit>
            <lower>-1e+16</lower>
            <upper>1e+16</upper>
          </limit>
          <dynamics>
            <spring_reference>0</spring_reference>
            <spring_stiffness>0</spring_stiffness>
          </dynamics>
          <use_parent_model_frame>1</use_parent_model_frame>
        </axis>
      </joint>
      <link name='hokuyo_link_fake'>
        <pose frame=''>0.33 0 0.279 0 -0 0</pose>
        <inertial>
          <mass>0.1</mass>
          <inertia>
            <ixx>1</ixx>
            <ixy>0</ixy>
            <ixz>0</ixz>
            <iyy>1</iyy>
            <iyz>0</iyz>
            <izz>1</izz>
          </inertia>
        </inertial>
        <visual name='visual'>
          <geometry>
            <mesh>
              <uri>model://hokuyo/meshes/hokuyo.dae</uri>
            </mesh>
          </geometry>
        </visual>
        <collision name='collision-base'>
          <pose frame=''>0 0 -0.0145 0 -0 0</pose>
          <geometry>
            <box>
              <size>0.05 0.05 0.041</size>
            </box>
          </geometry>
          <max_contacts>10</max_contacts>
          <surface>
            <contact>
              <ode/>
            </contact>
            <bounce/>
            <friction>
              <torsional>
                <ode/>
              </torsional>
              <ode/>
            </friction>
          </surface>
        </collision>
        <collision name='collision-top'>
          <pose frame=''>0 0 0.0205 0 -0 0</pose>
          <geometry>
            <cylinder>
              <radius>0.021</radius>
              <length>0.029</length>
            </cylinder>
          </geometry>
          <max_contacts>10</max_contacts>
          <surface>
            <contact>
              <ode/>
            </contact>
            <bounce/>
            <friction>
              <torsional>
                <ode/>
              </torsional>
              <ode/>
            </friction>
          </surface>
        </collision>
        <sensor name='laser' type='ray'>
          <pose frame=''>0 0 0.05 0 -0 0</pose>
          <topic>~/hokuyo_laser_fake</topic>
          <ray>
            <scan>
              <horizontal>
                <samples>640</samples>
                <resolution>1</resolution>
                <min_angle>-2.26889</min_angle>
                <max_angle>2.2689</max_angle>
              </horizontal>
              <vertical>
                <samples>1</samples>
                <min_angle>0</min_angle>
                <max_angle>0</max_angle>
              </vertical>
            </scan>
            <range>
              <min>0.08</min>
              <max>10</max>
              <resolution>0.01</resolution>
            </range>
          </ray>
          <plugin name='laser' filename='libgazebo_ros_laser.so'>
            <topicName>/hokuyo_laser_fake</topicName>
            <frameName>fr_nocorner_center_lidar</frameName>
          </plugin>
          <always_on>1</always_on>
          <update_rate>30</update_rate>
          <visualize>1</visualize>
        </sensor>
        <self_collide>0</self_collide>
        <enable_wind>0</enable_wind>
        <kinematic>0</kinematic>
      </link>
      <joint name='fr_nocorner_center_lidar_fake_joint' type='fixed'>
        <child>hokuyo_link_fake</child>
        <parent>base_footprint</parent>
        <axis>
          <xyz>0 1 0</xyz>
          <limit>
            <lower>-1e+16</lower>
            <upper>1e+16</upper>
          </limit>
          <dynamics>
            <spring_reference>0</spring_reference>
            <spring_stiffness>0</spring_stiffness>
          </dynamics>
          <use_parent_model_frame>1</use_parent_model_frame>
        </axis>
      </joint>
      <plugin name='gazebo_ros_control' filename='libgazebo_ros_control.so'>
        <robotNamespace>/raskar</robotNamespace>
        <robotSimType>gazebo_ros_control/DefaultRobotHWSim</robotSimType>
        <legacyModeNS>1</legacyModeNS>
      </plugin>
      <static>0</static>
      <plugin name='omni_steering' filename='libgazebo_ros_planar_move.so'>
        <commandTopic>cmd_vel</commandTopic>
        <odometryFrame>odom</odometryFrame>
        <odometryTopic>odom</odometryTopic>
        <odometryRate>50.0</odometryRate>
        <robotBaseFrame>base_footprint</robotBaseFrame>
        <publishTf>0</publishTf>
        <robotNamespace>/</robotNamespace>
      </plugin>
      <pose frame=''>0 0 0 0 -0 0</pose>
    </model>
    <state world_name='default'>
      <sim_time>34 273000000</sim_time>
      <real_time>59 744770184</real_time>
      <wall_time>1579107871 337057262</wall_time>
      <iterations>1312</iterations>
      <model name='ground_plane'>
        <pose frame=''>0 0 0 0 -0 0</pose>
        <scale>1 1 1</scale>
        <link name='link'>
          <pose frame=''>0 0 0 0 -0 0</pose>
          <velocity>0 0 0 0 -0 0</velocity>
          <acceleration>0 0 0 0 -0 0</acceleration>
          <wrench>0 0 0 0 -0 0</wrench>
        </link>
      </model>
      <model name='raskar_gazebo'>
        <pose frame=''>0.009817 -0.000282 0.034985 6e-06 8e-06 0.000338</pose>
        <scale>1 1 1</scale>
        <link name='base_footprint'>
          <pose frame=''>0.009817 -0.000282 0.034985 6e-06 8e-06 0.000338</pose>
          <velocity>0 -1e-06 2e-06 -3e-06 -2e-06 -1e-06</velocity>
          <acceleration>-0.000224 -0.000221 0.001912 -0.002569 -0.001713 -0.001178</acceleration>
          <wrench>-0.015388 -0.015154 0.131372 0 -0 0</wrench>
        </link>
        <link name='bk_left_wheel'>
          <pose frame=''>-0.250273 0.26663 0.063489 5e-06 0.128116 0.000339</pose>
          <velocity>0 0 -1e-06 0 6e-06 -1e-06</velocity>
          <acceleration>0.00019 1.5e-05 -0.001337 -0.00018 0.005784 -0.001243</acceleration>
          <wrench>0.000342 2.6e-05 -0.002406 0 -0 0</wrench>
        </link>
        <link name='bk_right_wheel'>
          <pose frame=''>-0.250092 -0.26737 0.063486 6e-06 0.13046 0.000339</pose>
          <velocity>-0 0 -1e-06 -1e-06 -4e-06 -1e-06</velocity>
          <acceleration>-0.000452 3.9e-05 -0.001218 -0.000575 -0.004492 -0.001133</acceleration>
          <wrench>-0.000813 7.1e-05 -0.002192 0 -0 0</wrench>
        </link>
        <link name='fr_left_wheel'>
          <pose frame=''>0.269727 0.266806 0.063485 9e-06 0.131342 0.000339</pose>
          <velocity>0 -0 -1e-06 6e-06 4e-06 -1e-06</velocity>
          <acceleration>0.000113 -0.000366 -0.001194 0.00577 0.00427 -0.00126</acceleration>
          <wrench>0.000203 -0.000659 -0.00215 0 -0 0</wrench>
        </link>
        <link name='fr_right_wheel'>
          <pose frame=''>0.269908 -0.267194 0.063481 7e-06 0.133768 0.000339</pose>
          <velocity>-0 -1e-06 7e-06 1.3e-05 -2.1e-05 -2e-06</velocity>
          <acceleration>-0.000355 -0.000808 0.007215 0.012739 -0.020853 -0.002214</acceleration>
          <wrench>-0.000639 -0.001454 0.012987 0 -0 0</wrench>
        </link>
        <link name='hokuyo_link_fake'>
          <pose frame=''>0.33982 -0.000172 0.313983 6e-06 8e-06 0.000338</pose>
          <velocity>-0 -0 2e-06 -2e-06 -1e-06 -1e-06</velocity>
          <acceleration>-0.000337 -0.000165 0.00232 -0.002065 -0.001304 -0.001006</acceleration>
          <wrench>-3.4e-05 -1.7e-05 0.000232 0 -0 0</wrench>
        </link>
      </model>
      <model name='unit_box'>
        <pose frame=''>2.0413 -1.48185 0.5 -0 -0 -0.017749</pose>
        <scale>1 1 1</scale>
        <link name='link'>
          <pose frame=''>2.0413 -1.48185 0.5 -0 -0 -0.017749</pose>
          <velocity>0 0 0 0 -0 0</velocity>
          <acceleration>-0 0 -0 -1e-06 -1e-06 0</acceleration>
          <wrench>-0 0 -0 0 -0 0</wrench>
        </link>
      </model>
      <model name='unit_box_0'>
        <pose frame=''>2.07553 -2.49486 0.5 0 0 -0.00269</pose>
        <scale>1 1 1</scale>
        <link name='link'>
          <pose frame=''>2.07553 -2.49486 0.5 0 0 -0.00269</pose>
          <velocity>0 0 0 0 -0 0</velocity>
          <acceleration>-0.021603 -9.7811 9.78159 0.712637 -0.04321 4.3e-05</acceleration>
          <wrench>-0.021603 -9.7811 9.78159 0 -0 0</wrench>
        </link>
      </model>
      <model name='unit_box_1'>
        <pose frame=''>1.07557 -2.47261 0.499995 0 1e-05 -0.002691</pose>
        <scale>1 1 1</scale>
        <link name='link'>
          <pose frame=''>1.07557 -2.47261 0.499995 0 1e-05 -0.002691</pose>
          <velocity>0 0 0 0 -0 0</velocity>
          <acceleration>0.010596 -0.006192 -9.78231 0.01242 0.021189 1.6e-05</acceleration>
          <wrench>0.010596 -0.006192 -9.78231 0 -0 0</wrench>
        </link>
      </model>
      <light name='sun'>
        <pose frame=''>0 0 10 0 -0 0</pose>
      </light>
    </state>
    <gui fullscreen='0'>
      <camera name='user_camera'>
        <pose frame=''>-2.33858 1.66353 1.17087 0 0.318082 -0.549156</pose>
        <view_controller>orbit</view_controller>
        <projection_type>perspective</projection_type>
      </camera>
    </gui>
    <model name='unit_box'>
      <pose frame=''>2.04443 -1.48499 0.5 0 -0 0</pose>
      <link name='link'>
        <inertial>
          <mass>1</mass>
          <inertia>
            <ixx>0.166667</ixx>
            <ixy>0</ixy>
            <ixz>0</ixz>
            <iyy>0.166667</iyy>
            <iyz>0</iyz>
            <izz>0.166667</izz>
          </inertia>
        </inertial>
        <collision name='collision'>
          <geometry>
            <box>
              <size>1 1 1</size>
            </box>
          </geometry>
          <max_contacts>10</max_contacts>
          <surface>
            <contact>
              <ode/>
            </contact>
            <bounce/>
            <friction>
              <torsional>
                <ode/>
              </torsional>
              <ode/>
            </friction>
          </surface>
        </collision>
        <visual name='visual'>
          <geometry>
            <box>
              <size>1 1 1</size>
            </box>
          </geometry>
          <material>
            <script>
              <name>Gazebo/Grey</name>
              <uri>file://media/materials/scripts/gazebo.material</uri>
            </script>
          </material>
        </visual>
        <self_collide>0</self_collide>
        <enable_wind>0</enable_wind>
        <kinematic>0</kinematic>
      </link>
    </model>
    <model name='unit_box_0'>
      <pose frame=''>2.04937 -2.49202 0.5 0 -0 0</pose>
      <link name='link'>
        <inertial>
          <mass>1</mass>
          <inertia>
            <ixx>0.166667</ixx>
            <ixy>0</ixy>
            <ixz>0</ixz>
            <iyy>0.166667</iyy>
            <iyz>0</iyz>
            <izz>0.166667</izz>
          </inertia>
        </inertial>
        <collision name='collision'>
          <geometry>
            <box>
              <size>1 1 1</size>
            </box>
          </geometry>
          <max_contacts>10</max_contacts>
          <surface>
            <contact>
              <ode/>
            </contact>
            <bounce/>
            <friction>
              <torsional>
                <ode/>
              </torsional>
              <ode/>
            </friction>
          </surface>
        </collision>
        <visual name='visual'>
          <geometry>
            <box>
              <size>1 1 1</size>
            </box>
          </geometry>
          <material>
            <script>
              <name>Gazebo/Grey</name>
              <uri>file://media/materials/scripts/gazebo.material</uri>
            </script>
          </material>
        </visual>
        <self_collide>0</self_collide>
        <enable_wind>0</enable_wind>
        <kinematic>0</kinematic>
      </link>
    </model>
    <model name='unit_box_1'>
      <pose frame=''>1.09859 -2.47233 0.5 0 -0 0</pose>
      <link name='link'>
        <inertial>
          <mass>1</mass>
          <inertia>
            <ixx>0.166667</ixx>
            <ixy>0</ixy>
            <ixz>0</ixz>
            <iyy>0.166667</iyy>
            <iyz>0</iyz>
            <izz>0.166667</izz>
          </inertia>
        </inertial>
        <collision name='collision'>
          <geometry>
            <box>
              <size>1 1 1</size>
            </box>
          </geometry>
          <max_contacts>10</max_contacts>
          <surface>
            <contact>
              <ode/>
            </contact>
            <bounce/>
            <friction>
              <torsional>
                <ode/>
              </torsional>
              <ode/>
            </friction>
          </surface>
        </collision>
        <visual name='visual'>
          <geometry>
            <box>
              <size>1 1 1</size>
            </box>
          </geometry>
          <material>
            <script>
              <name>Gazebo/Grey</name>
              <uri>file://media/materials/scripts/gazebo.material</uri>
            </script>
          </material>
        </visual>
        <self_collide>0</self_collide>
        <enable_wind>0</enable_wind>
        <kinematic>0</kinematic>
      </link>
    </model>
  </world>
</sdf>
